2019-01-10 18:35:59,111::DEBUG::[Register]: Registeration request received for userid 453.
2019-01-10 18:36:00,561::DEBUG::[Status Update]: UpdateFaceReconStatus API has been called successfully.
2019-01-10 18:36:00,562::DEBUG::[Status Update]: Data updated successfully
2019-01-10 18:42:58,407::DEBUG::[Check-in]: Check-in request recieved for userid 13 with imagepath http://wsautomatebanking.calibehr.com/UploadedImages/DailyAttendance/13_IN_umeshbahelia_03Dec2018.png
2019-01-10 18:43:40,461::DEBUG::[Check-in]: The Person identified in the image is ['Unknown'] for userid 13.
2019-01-10 18:43:40,529::DEBUG::[Check-in]: Updated Status in Database.
2019-01-10 18:43:40,530::DEBUG::[Check-in]: Check-in request successfully processed.
2019-01-10 18:53:55,087::DEBUG::[Check-in]: Check-in request recieved for userid 2 with imagepath 
2019-01-10 18:53:55,088::ERROR::[Check-in]: Unable to process Check-in request.
Traceback (most recent call last):
  File "E:\MachineLearning\face-recognition\CGI\ws.py", line 129, in check
  File "C:\ProgramData\Anaconda3\lib\site-packages\skimage\io\_io.py", line 62, in imread
    img = call_plugin('imread', fname, plugin=plugin, **plugin_args)
  File "C:\ProgramData\Anaconda3\lib\site-packages\skimage\io\manage_plugins.py", line 214, in call_plugin
    return func(*args, **kwargs)
  File "C:\ProgramData\Anaconda3\lib\site-packages\skimage\io\_plugins\pil_plugin.py", line 35, in imread
    with open(fname, 'rb') as f:
FileNotFoundError: [Errno 2] No such file or directory: ''
2019-01-10 18:58:40,927::DEBUG::[Check-in]: Check-in request recieved for userid 2 with imagepath 
2019-01-10 18:58:40,928::ERROR::[Check-in]: Unable to process Check-in request.
Traceback (most recent call last):
  File "E:\MachineLearning\face-recognition\CGI\ws.py", line 129, in check
  File "C:\ProgramData\Anaconda3\lib\site-packages\skimage\io\_io.py", line 62, in imread
    img = call_plugin('imread', fname, plugin=plugin, **plugin_args)
  File "C:\ProgramData\Anaconda3\lib\site-packages\skimage\io\manage_plugins.py", line 214, in call_plugin
    return func(*args, **kwargs)
  File "C:\ProgramData\Anaconda3\lib\site-packages\skimage\io\_plugins\pil_plugin.py", line 35, in imread
    with open(fname, 'rb') as f:
FileNotFoundError: [Errno 2] No such file or directory: ''
2019-01-10 19:12:05,996::DEBUG::[Check-in]: Check-in request recieved for userid 2 with imagepath 
2019-01-10 19:12:05,996::ERROR::[Check-in]: Unable to process Check-in request.
Traceback (most recent call last):
  File "E:\MachineLearning\face-recognition\CGI\ws.py", line 129, in check
  File "C:\ProgramData\Anaconda3\lib\site-packages\skimage\io\_io.py", line 62, in imread
    img = call_plugin('imread', fname, plugin=plugin, **plugin_args)
  File "C:\ProgramData\Anaconda3\lib\site-packages\skimage\io\manage_plugins.py", line 214, in call_plugin
    return func(*args, **kwargs)
  File "C:\ProgramData\Anaconda3\lib\site-packages\skimage\io\_plugins\pil_plugin.py", line 35, in imread
    with open(fname, 'rb') as f:
FileNotFoundError: [Errno 2] No such file or directory: ''
2019-01-10 19:16:20,778::DEBUG::[Check-in]: Check-in request recieved for userid 2 with imagepath http://wsbanking.go4automate.com/UploadedImages/DailyAttendance/2_IN_VibhutiKumar_10Jan2019.png
2019-01-10 19:17:02,406::DEBUG::[Check-in]: The Person identified in the image is ['Unknown'] for userid 2.
2019-01-10 19:17:02,407::DEBUG::[Check-in]: Check-in request recieved for userid 2 with imagepath http://wsbanking.go4automate.com/UploadedImages/DailyAttendance/2_IN_VibhutiKumar_10Jan2019.png
2019-01-10 19:17:02,424::DEBUG::[Check-in]: Updated Status in Database.
2019-01-10 19:17:02,425::DEBUG::[Check-in]: Check-in request successfully processed.
2019-01-10 19:17:43,785::DEBUG::[Check-in]: The Person identified in the image is ['746'] for userid 2.
2019-01-10 19:17:43,790::DEBUG::[Check-in]: Updated Status in Database.
2019-01-10 19:17:43,791::DEBUG::[Check-in]: Check-in request successfully processed.
2019-01-10 19:22:36,501::DEBUG::[Check-in]: Check-in request recieved for userid 2 with imagepath http://wsbanking.go4automate.com/UploadedImages/DailyAttendance/2_IN_VibhutiKumar_10Jan2019.png
2019-01-10 19:23:18,211::DEBUG::[Check-in]: The Person identified in the image is ['Unknown'] for userid 2.
2019-01-10 19:23:18,226::DEBUG::[Check-in]: Updated Status in Database.
2019-01-10 19:23:18,226::DEBUG::[Check-in]: Check-in request successfully processed.
